Workbook

Sheet Inicial 5Años
A1: N. | B1: APELLIDOS Y NOMBRES | C1: I BIM | D1: II BIM | E1: III BIM | F1: IV BIM | G1: PROMEDIO | H1: RENDIMIENTO ACADEMICO | I1: PENSION | O1: BALANCE INICIAL 5 AÑOS | X1: N. | Y1: APELLIDOS Y NOMBRES
K2: ACADEMICO | O2: POR CURSO | P2: PROM | Q2: PROYECTA
K3: Muy Bueno
K4: Bueno
K5: Regular
K6: Bajo
K8: PENSION
K9: Puntual
K10: Moroso
K11: Recontra Moroso

Sheet BalanceGeneralOrdenado
B2: BALANCE GENERALES DEL COLEGO
B4: NIVEL ACADEMICO GENERAL
B5: Muy Bueno | C5: =SUM(#REF!,'Inicial 5Años'!L3,#REF!,#REF!,#REF!,#REF!,#REF!,#REF!,#REF!,#REF!,#REF!,#REF!) -> #REF! | D5: =((100*C5)/(SUM(C5:C8)))/100 -> #REF!
B6: Bueno | C6: =SUM(#REF!,'Inicial 5Años'!L4,#REF!,#REF!,#REF!,#REF!,#REF!,#REF!,#REF!,#REF!,#REF!,#REF!) -> #REF! | D6: =((100*C6)/(SUM(C5:C8)))/100 -> #REF!
B7: Regular | C7: =SUM(#REF!,'Inicial 5Años'!L5,#REF!,#REF!,#REF!,#REF!,#REF!,#REF!,#REF!,#REF!,#REF!,#REF!) -> #REF! | D7: =((100*C7)/(SUM(C5:C8)))/100 -> #REF!
B8: Bajo | C8: =SUM(#REF!,'Inicial 5Años'!L6,#REF!,#REF!,#REF!,#REF!,#REF!,#REF!,#REF!,#REF!,#REF!,#REF!) -> #REF! | D8: =((100*C8)/(SUM(C5:C8)))/100 -> #REF!
B10: ESTADO DE PENSION GENERAL
B11: Puntual | C11: =SUM(#REF!,'Inicial 5Años'!L9,#REF!,#REF!,#REF!,#REF!,#REF!,#REF!,#REF!,#REF!,#REF!,#REF!) -> #REF! | D11: =((100*C11)/(SUM(C11:C13)))/100 -> #REF!
B12: Moroso | C12: =SUM(#REF!,'Inicial 5Años'!L10,#REF!,#REF!,#REF!,#REF!,#REF!,#REF!,#REF!,#REF!,#REF!,#REF!) -> #REF! | D12: =((100*C12)/(SUM(C11:C13)))/100 -> #REF!
B13: Recontra Moroso | C13: =SUM(#REF!,'Inicial 5Años'!L11,#REF!,#REF!,#REF!,#REF!,#REF!,#REF!,#REF!,#REF!,#REF!,#REF!) -> #REF! | D13: =((100*C13)/(SUM(C11:C13)))/100 -> #REF!
B15: ESCALAS DE NOTAS
B16: Muy Bueno | C16: 19 - 20
B17: Bueno | C17: 17 - 18
B18: Regular | C18: 14- 15 - 16
B19: Bajo | C19: 13 a menos
B22: NIVEL ACADEMICO POR SECCION | G22: POR SU AULA | K22: POR TODO EL COLEGIO
C23: Muy Bueno | D23: Bueno | E23: Regular | F23: Bajo | G23: Muy Bueno % | H23: Bueno % | I23: Regular % | J23: Bajo % | K23: Muy Bueno % | L23: Bueno % | M23: Regular % | N23: Bajo %
B24: 1er Grado | C24: =#REF! -> #REF! | D24: =#REF! -> #REF! | E24: =#REF! -> #REF! | F24: =#REF! -> #REF! | G24: =((100*C24)/(SUM(C24:F24)))/100 -> #REF! | H24: =((100*D24)/(SUM(C24:F24)))/100 -> #REF! | I24: =((100*E24)/(SUM(C24:F24)))/100 -> #REF! | J24: =((100*F24)/(SUM(C24:F24)))/100 -> #REF! | K24: =((100*C24)/(SUM($C$24:$F$35)))/100 -> #REF! | L24: =((100*D24)/(SUM($C$24:$F$35)))/100 -> #REF! | M24: =((100*E24)/(SUM($C$24:$F$35)))/100 -> #REF! | N24: =((100*F24)/(SUM($C$24:$F$35)))/100 -> #REF!
B25: 2do Grado | C25: =#REF! -> #REF! | D25: =#REF! -> #REF! | E25: =#REF! -> #REF! | F25: =#REF! -> #REF! | G25: =((100*C25)/(SUM(C25:F25)))/100 -> #REF! | H25: =((100*D25)/(SUM(C25:F25)))/100 -> #REF! | I25: =((100*E25)/(SUM(C25:F25)))/100 -> #REF! | J25: =((100*F25)/(SUM(C25:F25)))/100 -> #REF! | K25: =((100*C25)/(SUM($C$24:$F$35)))/100 -> #REF! | L25: =((100*D25)/(SUM($C$24:$F$35)))/100 -> #REF! | M25: =((100*E25)/(SUM($C$24:$F$35)))/100 -> #REF! | N25: =((100*F25)/(SUM($C$24:$F$35)))/100 -> #REF!
B26: 3er Grado | C26: =#REF! -> #REF! | D26: =#REF! -> #REF! | E26: =#REF! -> #REF! | F26: =#REF! -> #REF! | G26: =((100*C26)/(SUM(C26:F26)))/100 -> #REF! | H26: =((100*D26)/(SUM(C26:F26)))/100 -> #REF! | I26: =((100*E26)/(SUM(C26:F26)))/100 -> #REF! | J26: =((100*F26)/(SUM(C26:F26)))/100 -> #REF! | K26: =((100*C26)/(SUM($C$24:$F$35)))/100 -> #REF! | L26: =((100*D26)/(SUM($C$24:$F$35)))/100 -> #REF! | M26: =((100*E26)/(SUM($C$24:$F$35)))/100 -> #REF! | N26: =((100*F26)/(SUM($C$24:$F$35)))/100 -> #REF!
B27: Inicial 4 Años | C27: =#REF! -> #REF! | D27: =#REF! -> #REF! | E27: =#REF! -> #REF! | F27: =#REF! -> #REF! | G27: =((100*C27)/(SUM(C27:F27)))/100 -> #REF! | H27: =((100*D27)/(SUM(C27:F27)))/100 -> #REF! | I27: =((100*E27)/(SUM(C27:F27)))/100 -> #REF! | J27: =((100*F27)/(SUM(C27:F27)))/100 -> #REF! | K27: =((100*C27)/(SUM($C$24:$F$35)))/100 -> #REF! | L27: =((100*D27)/(SUM($C$24:$F$35)))/100 -> #REF! | M27: =((100*E27)/(SUM($C$24:$F$35)))/100 -> #REF! | N27: =((100*F27)/(SUM($C$24:$F$35)))/100 -> #REF!
B28: Inicial 5 Años | C28: ='Inicial 5Años'!L3 -> 0 | D28: ='Inicial 5Años'!L4 -> 0 | E28: ='Inicial 5Años'!L5 -> 0 | F28: ='Inicial 5Años'!L6 -> 0 | G28: =((100*C28)/(SUM(C28:F28)))/100 -> #DIV/0! | H28: =((100*D28)/(SUM(C28:F28)))/100 -> #DIV/0! | I28: =((100*E28)/(SUM(C28:F28)))/100 -> #DIV/0! | J28: =((100*F28)/(SUM(C28:F28)))/100 -> #DIV/0! | K28: =((100*C28)/(SUM($C$24:$F$35)))/100 -> #REF! | L28: =((100*D28)/(SUM($C$24:$F$35)))/100 -> #REF! | M28: =((100*E28)/(SUM($C$24:$F$35)))/100 -> #REF! | N28: =((100*F28)/(SUM($C$24:$F$35)))/100 -> #REF!
B29: 4to Grado | C29: =#REF! -> #REF! | D29: =#REF! -> #REF! | E29: =#REF! -> #REF! | F29: =#REF! -> #REF! | G29: =((100*C29)/(SUM(C29:F29)))/100 -> #REF! | H29: =((100*D29)/(SUM(C29:F29)))/100 -> #REF! | I29: =((100*E29)/(SUM(C29:F29)))/100 -> #REF! | J29: =((100*F29)/(SUM(C29:F29)))/100 -> #REF! | K29: =((100*C29)/(SUM($C$24:$F$35)))/100 -> #REF! | L29: =((100*D29)/(SUM($C$24:$F$35)))/100 -> #REF! | M29: =((100*E29)/(SUM($C$24:$F$35)))/100 -> #REF! | N29: =((100*F29)/(SUM($C$24:$F$35)))/100 -> #REF!
B30: 6to Grado | C30: =#REF! -> #REF! | D30: =#REF! -> #REF! | E30: =#REF! -> #REF! | F30: =#REF! -> #REF! | G30: =((100*C30)/(SUM(C30:F30)))/100 -> #REF! | H30: =((100*D30)/(SUM(C30:F30)))/100 -> #REF! | I30: =((100*E30)/(SUM(C30:F30)))/100 -> #REF! | J30: =((100*F30)/(SUM(C30:F30)))/100 -> #REF! | K30: =((100*C30)/(SUM($C$24:$F$35)))/100 -> #REF! | L30: =((100*D30)/(SUM($C$24:$F$35)))/100 -> #REF! | M30: =((100*E30)/(SUM($C$24:$F$35)))/100 -> #REF! | N30: =((100*F30)/(SUM($C$24:$F$35)))/100 -> #REF!
B31: 5to Grado | C31: =#REF! -> #REF! | D31: =#REF! -> #REF! | E31: =#REF! -> #REF! | F31: =#REF! -> #REF! | G31: =((100*C31)/(SUM(C31:F31)))/100 -> #REF! | H31: =((100*D31)/(SUM(C31:F31)))/100 -> #REF! | I31: =((100*E31)/(SUM(C31:F31)))/100 -> #REF! | J31: =((100*F31)/(SUM(C31:F31)))/100 -> #REF! | K31: =((100*C31)/(SUM($C$24:$F$35)))/100 -> #REF! | L31: =((100*D31)/(SUM($C$24:$F$35)))/100 -> #REF! | M31: =((100*E31)/(SUM($C$24:$F$35)))/100 -> #REF! | N31: =((100*F31)/(SUM($C$24:$F$35)))/100 -> #REF!
B32: 2do Año | C32: =#REF! -> #REF! | D32: =#REF! -> #REF! | E32: =#REF! -> #REF! | F32: =#REF! -> #REF! | G32: =((100*C32)/(SUM(C32:F32)))/100 -> #REF! | H32: =((100*D32)/(SUM(C32:F32)))/100 -> #REF! | I32: =((100*E32)/(SUM(C32:F32)))/100 -> #REF! | J32: =((100*F32)/(SUM(C32:F32)))/100 -> #REF! | K32: =((100*C32)/(SUM($C$24:$F$35)))/100 -> #REF! | L32: =((100*D32)/(SUM($C$24:$F$35)))/100 -> #REF! | M32: =((100*E32)/(SUM($C$24:$F$35)))/100 -> #REF! | N32: =((100*F32)/(SUM($C$24:$F$35)))/100 -> #REF!
B33: 3er Año | C33: =#REF! -> #REF! | D33: =#REF! -> #REF! | E33: =#REF! -> #REF! | F33: =#REF! -> #REF! | G33: =((100*C33)/(SUM(C33:F33)))/100 -> #REF! | H33: =((100*D33)/(SUM(C33:F33)))/100 -> #REF! | I33: =((100*E33)/(SUM(C33:F33)))/100 -> #REF! | J33: =((100*F33)/(SUM(C33:F33)))/100 -> #REF! | K33: =((100*C33)/(SUM($C$24:$F$35)))/100 -> #REF! | L33: =((100*D33)/(SUM($C$24:$F$35)))/100 -> #REF! | M33: =((100*E33)/(SUM($C$24:$F$35)))/100 -> #REF! | N33: =((100*F33)/(SUM($C$24:$F$35)))/100 -> #REF!
B34: Avanzada | C34: =#REF! -> #REF! | D34: =#REF! -> #REF! | E34: =#REF! -> #REF! | F34: =#REF! -> #REF! | G34: =((100*C34)/(SUM(C34:F34)))/100 -> #REF! | H34: =((100*D34)/(SUM(C34:F34)))/100 -> #REF! | I34: =((100*E34)/(SUM(C34:F34)))/100 -> #REF! | J34: =((100*F34)/(SUM(C34:F34)))/100 -> #REF! | K34: =((100*C34)/(SUM($C$24:$F$35)))/100 -> #REF! | L34: =((100*D34)/(SUM($C$24:$F$35)))/100 -> #REF! | M34: =((100*E34)/(SUM($C$24:$F$35)))/100 -> #REF! | N34: =((100*F34)/(SUM($C$24:$F$35)))/100 -> #REF!
B35: 1er Año | C35: =#REF! -> #REF! | D35: =#REF! -> #REF! | E35: =#REF! -> #REF! | F35: =#REF! -> #REF! | G35: =((100*C35)/(SUM(C35:F35)))/100 -> #REF! | H35: =((100*D35)/(SUM(C35:F35)))/100 -> #REF! | I35: =((100*E35)/(SUM(C35:F35)))/100 -> #REF! | J35: =((100*F35)/(SUM(C35:F35)))/100 -> #REF! | K35: =((100*C35)/(SUM($C$24:$F$35)))/100 -> #REF! | L35: =((100*D35)/(SUM($C$24:$F$35)))/100 -> #REF! | M35: =((100*E35)/(SUM($C$24:$F$35)))/100 -> #REF! | N35: =((100*F35)/(SUM($C$24:$F$35)))/100 -> #REF!
B38: ESTADO DE PENSIONES POR SECCIONES | F38: POR SU AULA | I38: POR TODO EL COLEGIO
C39: Puntual | D39: Moroso | E39: Recontra Moroso | F39: Puntual % | G39: Moroso % | H39: Recontra Moroso % | I39: Puntual % | J39: Moroso % | K39: Recontra Moroso %
B40: 6to Grado | C40: =#REF! -> #REF! | D40: =#REF! -> #REF! | E40: =#REF! -> #REF! | F40: =((100*C40)/(SUM(C40:E40)))/100 -> #REF! | G40: =((100*D40)/(SUM(C40:E40)))/100 -> #REF! | H40: =((100*E40)/(SUM(C40:E40)))/100 -> #REF! | I40: =((100*C40)/(SUM($C$40:$E$51)))/100 -> #REF! | J40: =((100*D40)/(SUM($C$40:$E$51)))/100 -> #REF! | K40: =((100*E40)/(SUM($C$40:$E$51)))/100 -> #REF!
B41: 3er Año | C41: =#REF! -> #REF! | D41: =#REF! -> #REF! | E41: =#REF! -> #REF! | F41: =((100*C41)/(SUM(C41:E41)))/100 -> #REF! | G41: =((100*D41)/(SUM(C41:E41)))/100 -> #REF! | H41: =((100*E41)/(SUM(C41:E41)))/100 -> #REF! | I41: =((100*C41)/(SUM($C$40:$E$51)))/100 -> #REF! | J41: =((100*D41)/(SUM($C$40:$E$51)))/100 -> #REF! | K41: =((100*E41)/(SUM($C$40:$E$51)))/100 -> #REF!
B42: 2do Año | C42: =#REF! -> #REF! | D42: =#REF! -> #REF! | E42: =#REF! -> #REF! | F42: =((100*C42)/(SUM(C42:E42)))/100 -> #REF! | G42: =((100*D42)/(SUM(C42:E42)))/100 -> #REF! | H42: =((100*E42)/(SUM(C42:E42)))/100 -> #REF! | I42: =((100*C42)/(SUM($C$40:$E$51)))/100 -> #REF! | J42: =((100*D42)/(SUM($C$40:$E$51)))/100 -> #REF! | K42: =((100*E42)/(SUM($C$40:$E$51)))/100 -> #REF!
B43: 5to Grado | C43: =#REF! -> #REF! | D43: =#REF! -> #REF! | E43: =#REF! -> #REF! | F43: =((100*C43)/(SUM(C43:E43)))/100 -> #REF! | G43: =((100*D43)/(SUM(C43:E43)))/100 -> #REF! | H43: =((100*E43)/(SUM(C43:E43)))/100 -> #REF! | I43: =((100*C43)/(SUM($C$40:$E$51)))/100 -> #REF! | J43: =((100*D43)/(SUM($C$40:$E$51)))/100 -> #REF! | K43: =((100*E43)/(SUM($C$40:$E$51)))/100 -> #REF!
B44: 2do Grado | C44: =#REF! -> #REF! | D44: =#REF! -> #REF! | E44: =#REF! -> #REF! | F44: =((100*C44)/(SUM(C44:E44)))/100 -> #REF! | G44: =((100*D44)/(SUM(C44:E44)))/100 -> #REF! | H44: =((100*E44)/(SUM(C44:E44)))/100 -> #REF! | I44: =((100*C44)/(SUM($C$40:$E$51)))/100 -> #REF! | J44: =((100*D44)/(SUM($C$40:$E$51)))/100 -> #REF! | K44: =((100*E44)/(SUM($C$40:$E$51)))/100 -> #REF!
B45: 1er Año | C45: =#REF! -> #REF! | D45: =#REF! -> #REF! | E45: =#REF! -> #REF! | F45: =((100*C45)/(SUM(C45:E45)))/100 -> #REF! | G45: =((100*D45)/(SUM(C45:E45)))/100 -> #REF! | H45: =((100*E45)/(SUM(C45:E45)))/100 -> #REF! | I45: =((100*C45)/(SUM($C$40:$E$51)))/100 -> #REF! | J45: =((100*D45)/(SUM($C$40:$E$51)))/100 -> #REF! | K45: =((100*E45)/(SUM($C$40:$E$51)))/100 -> #REF!
B46: 4to Grado | C46: =#REF! -> #REF! | D46: =#REF! -> #REF! | E46: =#REF! -> #REF! | F46: =((100*C46)/(SUM(C46:E46)))/100 -> #REF! | G46: =((100*D46)/(SUM(C46:E46)))/100 -> #REF! | H46: =((100*E46)/(SUM(C46:E46)))/100 -> #REF! | I46: =((100*C46)/(SUM($C$40:$E$51)))/100 -> #REF! | J46: =((100*D46)/(SUM($C$40:$E$51)))/100 -> #REF! | K46: =((100*E46)/(SUM($C$40:$E$51)))/100 -> #REF!
B47: Avanzada | C47: =#REF! -> #REF! | D47: =#REF! -> #REF! | E47: =#REF! -> #REF! | F47: =((100*C47)/(SUM(C47:E47)))/100 -> #REF! | G47: =((100*D47)/(SUM(C47:E47)))/100 -> #REF! | H47: =((100*E47)/(SUM(C47:E47)))/100 -> #REF! | I47: =((100*C47)/(SUM($C$40:$E$51)))/100 -> #REF! | J47: =((100*D47)/(SUM($C$40:$E$51)))/100 -> #REF! | K47: =((100*E47)/(SUM($C$40:$E$51)))/100 -> #REF!
B48: Inicial 4 Años | C48: =#REF! -> #REF! | D48: =#REF! -> #REF! | E48: =#REF! -> #REF! | F48: =((100*C48)/(SUM(C48:E48)))/100 -> #REF! | G48: =((100*D48)/(SUM(C48:E48)))/100 -> #REF! | H48: =((100*E48)/(SUM(C48:E48)))/100 -> #REF! | I48: =((100*C48)/(SUM($C$40:$E$51)))/100 -> #REF! | J48: =((100*D48)/(SUM($C$40:$E$51)))/100 -> #REF! | K48: =((100*E48)/(SUM($C$40:$E$51)))/100 -> #REF!
...
